<?xml version="1.0"?>
<robot name="box">
  <link name="world"/>

  <joint name="fixed" type="fixed">
    <parent link="world"/>
    <child link="base_link"/>
    <origin xyz="0 0 0"/>
  </joint>

  <link name="base_link">
    <contact>
      <lateral_friction value="1.0"/>
      <spinning_friction value=".001"/>
    </contact>
    <inertial>
      <origin rpy="0 0 0" xyz="0 0 0"/>
      <mass value="0.0"/>
      <inertia ixx="1" ixy="0" ixz="0" iyy="1" iyz="0" izz="1"/>
    </inertial>
    <visual>
      <origin rpy="0 0 0" xyz="0.0 0.0 -0.075"/>
      <geometry>
        <box size="0.40 0.20 0.03"/>
      </geometry>
      <material name="blockmat">
        <color rgba="0.1 0.7 0.1 1"/>
      </material>
    </visual>
    <collision>
      <origin rpy="0 0 0" xyz="0.0 0.0 -0.075"/>
      <geometry>
        <box size="0.40 0.20 0.03"/>
      </geometry>
    </collision>
    <visual>
      <origin rpy="0 0 0" xyz="0.0 -0.1 0.0"/>
      <geometry>
        <box size="0.40 0.025 0.15"/>
      </geometry>
      <material name="blockmat">
        <color rgba="0.1 0.7 0.1 1"/>
      </material>
    </visual>
    <collision>
      <origin rpy="0 0 0" xyz="0.0 -0.1 0.0"/>
      <geometry>
        <box size="0.40 0.025 0.15"/>
      </geometry>
    </collision>
    <visual>
      <origin rpy="0 0 1.570796" xyz="0.2 0.0 0.0"/>
      <geometry>
        <box size="0.20 0.025 0.15"/>
      </geometry>
      <material name="blockmat">
        <color rgba="0.1 0.7 0.1 1"/>
      </material>
    </visual>
    <collision>
      <origin rpy="0 0 1.570796" xyz="0.2 0.0 0.0"/>
      <geometry>
        <box size="0.20 0.025 0.15"/>
      </geometry>
    </collision>
    <visual>
      <origin rpy="0 0 0" xyz="0.0 0.1 0.0"/>
      <geometry>
        <box size="0.40 0.025 0.15"/>
      </geometry>
      <material name="blockmat">
        <color rgba="0.1 0.7 0.1 1"/>
      </material>
    </visual>
    <collision>
      <origin rpy="0 0 0" xyz="0.0 0.1 0.0"/>
      <geometry>
        <box size="0.40 0.025 0.15"/>
      </geometry>
    </collision>
    <visual>
      <origin rpy="0 0 1.570796" xyz="-0.2 0.0 0.0"/>
      <geometry>
        <box size="0.20 0.025 0.15"/>
      </geometry>
      <material name="blockmat">
        <color rgba="0.1 0.7 0.1 1"/>
      </material>
    </visual>
    <collision>
      <origin rpy="0 0 1.570796" xyz="-0.2 0.0 0.0"/>
      <geometry>
        <box size="0.20 0.025 0.15"/>
      </geometry>
    </collision>
  </link>

  <joint name="joint_baselink_coverlink" type="continuous">
    <parent link="base_link"/>
    <child link="cover_link"/>
    <dynamics damping="1.0" friction="0.0001"/>
    <origin xyz="0 0.1 0.075"/>
    <axis xyz="-1 0 0"/>
    <limit lower="0.0" upper="1.570796"/>
  </joint>

  <link name="cover_link">
    <contact>
      <lateral_friction value="100.0"/>
      <spinning_friction value=".001"/>
    </contact>
    <inertial>
      <origin rpy="0 0 0" xyz="0 -0.1 0"/>
      <mass value="0.0002"/>
      <inertia ixx="1" ixy="0" ixz="0" iyy="1" iyz="0" izz="1"/>
    </inertial>
    <visual>
      <origin rpy="0 0 0" xyz="0.0 -0.1 0.0"/>
      <geometry>
        <box size="0.40 0.20 0.03"/>
      </geometry>
      <material name="blockmat">
        <color rgba="0.1 0.7 0.1 1"/>
      </material>
    </visual>
    <collision>
      <origin rpy="0 0 0" xyz="0.0 -0.1 0.0"/>
      <geometry>
        <box size="0.40 0.20 0.03"/>
      </geometry>
    </collision>
    <visual>
      <origin rpy="0 0 0" xyz="0.0 -0.2 0.0"/>
      <geometry>
        <box size="0.08 0.08 0.03"/>
      </geometry>
      <material name="blockmat">
        <color rgba="0.1 0.7 0.1 1"/>
      </material>
    </visual>
    <collision>
      <origin rpy="0 0 0" xyz="0.0 -0.2 0.0"/>
      <geometry>
        <box size="0.08 0.08 0.03"/>
      </geometry>
    </collision>
  </link>
</robot>
